Watching for file changes with StatReloader
Watching for file changes with StatReloader
Watching for file changes with StatReloader
Watching for file changes with StatReloader
Watching for file changes with StatReloader
Watching for file changes with StatReloader
Watching for file changes with StatReloader
Watching for file changes with StatReloader
Watching for file changes with StatReloader
Watching for file changes with StatReloader
Watching for file changes with StatReloader
Watching for file changes with StatReloader
Internal Server Error: /
Traceback (most recent call last):
  File "/usr/local/lib/python3.13/site-packages/django/core/handlers/exception.py", line 55, in inner
    response = get_response(request)
  File "/usr/local/lib/python3.13/site-packages/django/core/handlers/base.py", line 197, in _get_response
    response = wrapped_callback(request, *callback_args, **callback_kwargs)
  File "/backend/backend/views.py", line 25, in index
    if currentUser['images'][0]:
       ~~~~~~~~~~~^^^^^^^^^^
KeyError: 'images'
Internal Server Error: /
Traceback (most recent call last):
  File "/usr/local/lib/python3.13/site-packages/django/core/handlers/exception.py", line 55, in inner
    response = get_response(request)
  File "/usr/local/lib/python3.13/site-packages/django/core/handlers/base.py", line 197, in _get_response
    response = wrapped_callback(request, *callback_args, **callback_kwargs)
  File "/backend/backend/views.py", line 25, in index
    if currentUser['images'][0]:
       ~~~~~~~~~~~^^^^^^^^^^
KeyError: 'images'
Internal Server Error: /
Traceback (most recent call last):
  File "/usr/local/lib/python3.13/site-packages/django/core/handlers/exception.py", line 55, in inner
    response = get_response(request)
  File "/usr/local/lib/python3.13/site-packages/django/core/handlers/base.py", line 197, in _get_response
    response = wrapped_callback(request, *callback_args, **callback_kwargs)
  File "/backend/backend/views.py", line 25, in index
    if currentUser['images'][0]:
       ~~~~~~~~~~~^^^^^^^^^^
KeyError: 'images'
Not Found: /getToken/
Internal Server Error: /
Traceback (most recent call last):
  File "/usr/local/lib/python3.13/site-packages/django/core/handlers/exception.py", line 55, in inner
    response = get_response(request)
  File "/usr/local/lib/python3.13/site-packages/django/core/handlers/base.py", line 197, in _get_response
    response = wrapped_callback(request, *callback_args, **callback_kwargs)
  File "/backend/backend/views.py", line 25, in index
    if currentUser['images'][0]:
       ~~~~~~~~~~~^^^^^^^^^^
KeyError: 'images'
Not Found: /getToken/
Internal Server Error: /
Traceback (most recent call last):
  File "/usr/local/lib/python3.13/site-packages/django/core/handlers/exception.py", line 55, in inner
    response = get_response(request)
  File "/usr/local/lib/python3.13/site-packages/django/core/handlers/base.py", line 197, in _get_response
    response = wrapped_callback(request, *callback_args, **callback_kwargs)
  File "/backend/backend/views.py", line 25, in index
    if currentUser['images'][0]:
       ~~~~~~~~~~~^^^^^^^^^^
KeyError: 'images'
Internal Server Error: /
Traceback (most recent call last):
  File "/usr/local/lib/python3.13/site-packages/django/core/handlers/exception.py", line 55, in inner
    response = get_response(request)
  File "/usr/local/lib/python3.13/site-packages/django/core/handlers/base.py", line 197, in _get_response
    response = wrapped_callback(request, *callback_args, **callback_kwargs)
  File "/backend/backend/views.py", line 25, in index
    if currentUser['images'][0]:
       ~~~~~~~~~~~^^^^^^^^^^
KeyError: 'images'
Internal Server Error: /
Traceback (most recent call last):
  File "/usr/local/lib/python3.13/site-packages/django/core/handlers/exception.py", line 55, in inner
    response = get_response(request)
  File "/usr/local/lib/python3.13/site-packages/django/core/handlers/base.py", line 197, in _get_response
    response = wrapped_callback(request, *callback_args, **callback_kwargs)
  File "/backend/backend/views.py", line 25, in index
    if currentUser['images'][0]:
       ~~~~~~~~~~~^^^^^^^^^^
KeyError: 'images'
Internal Server Error: /
Traceback (most recent call last):
  File "/usr/local/lib/python3.13/site-packages/django/core/handlers/exception.py", line 55, in inner
    response = get_response(request)
  File "/usr/local/lib/python3.13/site-packages/django/core/handlers/base.py", line 197, in _get_response
    response = wrapped_callback(request, *callback_args, **callback_kwargs)
  File "/backend/backend/views.py", line 25, in index
    if currentUser['images'][0]:
       ~~~~~~~~~~~^^^^^^^^^^
KeyError: 'images'
Internal Server Error: /
Traceback (most recent call last):
  File "/usr/local/lib/python3.13/site-packages/django/core/handlers/exception.py", line 55, in inner
    response = get_response(request)
  File "/usr/local/lib/python3.13/site-packages/django/core/handlers/base.py", line 197, in _get_response
    response = wrapped_callback(request, *callback_args, **callback_kwargs)
  File "/backend/backend/views.py", line 25, in index
    if currentUser['images'][0]:
       ~~~~~~~~~~~^^^^^^^^^^
KeyError: 'images'
Internal Server Error: /
Traceback (most recent call last):
  File "/usr/local/lib/python3.13/site-packages/django/core/handlers/exception.py", line 55, in inner
    response = get_response(request)
  File "/usr/local/lib/python3.13/site-packages/django/core/handlers/base.py", line 197, in _get_response
    response = wrapped_callback(request, *callback_args, **callback_kwargs)
  File "/backend/backend/views.py", line 25, in index
    if currentUser['images'][0]:
       ~~~~~~~~~~~^^^^^^^^^^
KeyError: 'images'
Internal Server Error: /
Traceback (most recent call last):
  File "/usr/local/lib/python3.13/site-packages/django/core/handlers/exception.py", line 55, in inner
    response = get_response(request)
  File "/usr/local/lib/python3.13/site-packages/django/core/handlers/base.py", line 197, in _get_response
    response = wrapped_callback(request, *callback_args, **callback_kwargs)
  File "/backend/backend/views.py", line 25, in index
    if currentUser['images'][0]:
       ~~~~~~~~~~~^^^^^^^^^^
KeyError: 'images'
Internal Server Error: /
Traceback (most recent call last):
  File "/usr/local/lib/python3.13/site-packages/django/core/handlers/exception.py", line 55, in inner
    response = get_response(request)
  File "/usr/local/lib/python3.13/site-packages/django/core/handlers/base.py", line 197, in _get_response
    response = wrapped_callback(request, *callback_args, **callback_kwargs)
  File "/backend/backend/views.py", line 25, in index
    if currentUser['images'][0]:
       ~~~~~~~~~~~^^^^^^^^^^
KeyError: 'images'
Internal Server Error: /
Traceback (most recent call last):
  File "/usr/local/lib/python3.13/site-packages/django/core/handlers/exception.py", line 55, in inner
    response = get_response(request)
  File "/usr/local/lib/python3.13/site-packages/django/core/handlers/base.py", line 197, in _get_response
    response = wrapped_callback(request, *callback_args, **callback_kwargs)
  File "/backend/backend/views.py", line 25, in index
    if currentUser['images'][0]:
       ~~~~~~~~~~~^^^^^^^^^^
KeyError: 'images'
Not Found: /getToken/
Internal Server Error: /
Traceback (most recent call last):
  File "/usr/local/lib/python3.13/site-packages/django/core/handlers/exception.py", line 55, in inner
    response = get_response(request)
  File "/usr/local/lib/python3.13/site-packages/django/core/handlers/base.py", line 197, in _get_response
    response = wrapped_callback(request, *callback_args, **callback_kwargs)
  File "/backend/backend/views.py", line 25, in index
    if currentUser['images'][0]:
       ~~~~~~~~~~~^^^^^^^^^^
KeyError: 'images'
Not Found: /getToken/
Internal Server Error: /
Traceback (most recent call last):
  File "/usr/local/lib/python3.13/site-packages/django/core/handlers/exception.py", line 55, in inner
    response = get_response(request)
  File "/usr/local/lib/python3.13/site-packages/django/core/handlers/base.py", line 197, in _get_response
    response = wrapped_callback(request, *callback_args, **callback_kwargs)
  File "/backend/backend/views.py", line 25, in index
    if currentUser['images'][0]:
       ~~~~~~~~~~~^^^^^^^^^^
KeyError: 'images'
Internal Server Error: /
Traceback (most recent call last):
  File "/usr/local/lib/python3.13/site-packages/django/core/handlers/exception.py", line 55, in inner
    response = get_response(request)
  File "/usr/local/lib/python3.13/site-packages/django/core/handlers/base.py", line 197, in _get_response
    response = wrapped_callback(request, *callback_args, **callback_kwargs)
  File "/backend/backend/views.py", line 25, in index
    if currentUser['images'][0]:
       ~~~~~~~~~~~^^^^^^^^^^
KeyError: 'images'
Internal Server Error: /
Traceback (most recent call last):
  File "/usr/local/lib/python3.13/site-packages/django/core/handlers/exception.py", line 55, in inner
    response = get_response(request)
  File "/usr/local/lib/python3.13/site-packages/django/core/handlers/base.py", line 197, in _get_response
    response = wrapped_callback(request, *callback_args, **callback_kwargs)
  File "/backend/backend/views.py", line 25, in index
    if currentUser['images'][0]:
       ~~~~~~~~~~~^^^^^^^^^^
KeyError: 'images'
Internal Server Error: /
Traceback (most recent call last):
  File "/usr/local/lib/python3.13/site-packages/django/core/handlers/exception.py", line 55, in inner
    response = get_response(request)
  File "/usr/local/lib/python3.13/site-packages/django/core/handlers/base.py", line 197, in _get_response
    response = wrapped_callback(request, *callback_args, **callback_kwargs)
  File "/backend/backend/views.py", line 25, in index
    if currentUser['images'][0]:
       ~~~~~~~~~~~^^^^^^^^^^
KeyError: 'images'
Internal Server Error: /
Traceback (most recent call last):
  File "/usr/local/lib/python3.13/site-packages/django/core/handlers/exception.py", line 55, in inner
    response = get_response(request)
  File "/usr/local/lib/python3.13/site-packages/django/core/handlers/base.py", line 197, in _get_response
    response = wrapped_callback(request, *callback_args, **callback_kwargs)
  File "/backend/backend/views.py", line 25, in index
    if currentUser['images'][0]:
       ~~~~~~~~~~~^^^^^^^^^^
KeyError: 'images'
Internal Server Error: /
Traceback (most recent call last):
  File "/usr/local/lib/python3.13/site-packages/django/core/handlers/exception.py", line 55, in inner
    response = get_response(request)
  File "/usr/local/lib/python3.13/site-packages/django/core/handlers/base.py", line 197, in _get_response
    response = wrapped_callback(request, *callback_args, **callback_kwargs)
  File "/backend/backend/views.py", line 25, in index
    if currentUser['images'][0]:
       ~~~~~~~~~~~^^^^^^^^^^
KeyError: 'images'
Internal Server Error: /
Traceback (most recent call last):
  File "/usr/local/lib/python3.13/site-packages/django/core/handlers/exception.py", line 55, in inner
    response = get_response(request)
  File "/usr/local/lib/python3.13/site-packages/django/core/handlers/base.py", line 197, in _get_response
    response = wrapped_callback(request, *callback_args, **callback_kwargs)
  File "/backend/backend/views.py", line 25, in index
    if currentUser['images'][0]:
       ~~~~~~~~~~~^^^^^^^^^^
KeyError: 'images'
Internal Server Error: /
Traceback (most recent call last):
  File "/usr/local/lib/python3.13/site-packages/django/core/handlers/exception.py", line 55, in inner
    response = get_response(request)
  File "/usr/local/lib/python3.13/site-packages/django/core/handlers/base.py", line 197, in _get_response
    response = wrapped_callback(request, *callback_args, **callback_kwargs)
  File "/backend/backend/views.py", line 25, in index
    if currentUser['images'][0]:
       ~~~~~~~~~~~^^^^^^^^^^
KeyError: 'images'
Internal Server Error: /
Traceback (most recent call last):
  File "/usr/local/lib/python3.13/site-packages/django/core/handlers/exception.py", line 55, in inner
    response = get_response(request)
  File "/usr/local/lib/python3.13/site-packages/django/core/handlers/base.py", line 197, in _get_response
    response = wrapped_callback(request, *callback_args, **callback_kwargs)
  File "/backend/backend/views.py", line 25, in index
    if currentUser['images'][0]:
       ~~~~~~~~~~~^^^^^^^^^^
KeyError: 'images'
Internal Server Error: /
Traceback (most recent call last):
  File "/usr/local/lib/python3.13/site-packages/django/core/handlers/exception.py", line 55, in inner
    response = get_response(request)
  File "/usr/local/lib/python3.13/site-packages/django/core/handlers/base.py", line 197, in _get_response
    response = wrapped_callback(request, *callback_args, **callback_kwargs)
  File "/backend/backend/views.py", line 25, in index
    if currentUser['images'][0]:
       ~~~~~~~~~~~^^^^^^^^^^
KeyError: 'images'
Internal Server Error: /
Traceback (most recent call last):
  File "/usr/local/lib/python3.13/site-packages/django/core/handlers/exception.py", line 55, in inner
    response = get_response(request)
  File "/usr/local/lib/python3.13/site-packages/django/core/handlers/base.py", line 197, in _get_response
    response = wrapped_callback(request, *callback_args, **callback_kwargs)
  File "/backend/backend/views.py", line 25, in index
    if currentUser['images'][0]:
       ~~~~~~~~~~~^^^^^^^^^^
KeyError: 'images'
Internal Server Error: /
Traceback (most recent call last):
  File "/usr/local/lib/python3.13/site-packages/django/core/handlers/exception.py", line 55, in inner
    response = get_response(request)
  File "/usr/local/lib/python3.13/site-packages/django/core/handlers/base.py", line 197, in _get_response
    response = wrapped_callback(request, *callback_args, **callback_kwargs)
  File "/backend/backend/views.py", line 25, in index
    if currentUser['images'][0]:
       ~~~~~~~~~~~^^^^^^^^^^
KeyError: 'images'
Internal Server Error: /
Traceback (most recent call last):
  File "/usr/local/lib/python3.13/site-packages/django/core/handlers/exception.py", line 55, in inner
    response = get_response(request)
  File "/usr/local/lib/python3.13/site-packages/django/core/handlers/base.py", line 197, in _get_response
    response = wrapped_callback(request, *callback_args, **callback_kwargs)
  File "/backend/backend/views.py", line 25, in index
    if currentUser['images'][0]:
       ~~~~~~~~~~~^^^^^^^^^^
KeyError: 'images'
Internal Server Error: /
Traceback (most recent call last):
  File "/usr/local/lib/python3.13/site-packages/django/core/handlers/exception.py", line 55, in inner
    response = get_response(request)
  File "/usr/local/lib/python3.13/site-packages/django/core/handlers/base.py", line 197, in _get_response
    response = wrapped_callback(request, *callback_args, **callback_kwargs)
  File "/backend/backend/views.py", line 25, in index
    if currentUser['images'][0]:
       ~~~~~~~~~~~^^^^^^^^^^
KeyError: 'images'
Internal Server Error: /
Traceback (most recent call last):
  File "/usr/local/lib/python3.13/site-packages/django/core/handlers/exception.py", line 55, in inner
    response = get_response(request)
  File "/usr/local/lib/python3.13/site-packages/django/core/handlers/base.py", line 197, in _get_response
    response = wrapped_callback(request, *callback_args, **callback_kwargs)
  File "/backend/backend/views.py", line 25, in index
    if currentUser['images'][0]:
       ~~~~~~~~~~~^^^^^^^^^^
KeyError: 'images'
Internal Server Error: /
Traceback (most recent call last):
  File "/usr/local/lib/python3.13/site-packages/django/core/handlers/exception.py", line 55, in inner
    response = get_response(request)
  File "/usr/local/lib/python3.13/site-packages/django/core/handlers/base.py", line 197, in _get_response
    response = wrapped_callback(request, *callback_args, **callback_kwargs)
  File "/backend/backend/views.py", line 25, in index
    if currentUser['images'][0]:
       ~~~~~~~~~~~^^^^^^^^^^
KeyError: 'images'
Internal Server Error: /
Traceback (most recent call last):
  File "/usr/local/lib/python3.13/site-packages/django/core/handlers/exception.py", line 55, in inner
    response = get_response(request)
  File "/usr/local/lib/python3.13/site-packages/django/core/handlers/base.py", line 197, in _get_response
    response = wrapped_callback(request, *callback_args, **callback_kwargs)
  File "/backend/backend/views.py", line 25, in index
    if currentUser['images'][0]:
       ~~~~~~~~~~~^^^^^^^^^^
KeyError: 'images'
Internal Server Error: /
Traceback (most recent call last):
  File "/usr/local/lib/python3.13/site-packages/django/core/handlers/exception.py", line 55, in inner
    response = get_response(request)
  File "/usr/local/lib/python3.13/site-packages/django/core/handlers/base.py", line 197, in _get_response
    response = wrapped_callback(request, *callback_args, **callback_kwargs)
  File "/backend/backend/views.py", line 25, in index
    if currentUser['images'][0]:
       ~~~~~~~~~~~^^^^^^^^^^
KeyError: 'images'
Internal Server Error: /
Traceback (most recent call last):
  File "/usr/local/lib/python3.13/site-packages/django/core/handlers/exception.py", line 55, in inner
    response = get_response(request)
  File "/usr/local/lib/python3.13/site-packages/django/core/handlers/base.py", line 197, in _get_response
    response = wrapped_callback(request, *callback_args, **callback_kwargs)
  File "/backend/backend/views.py", line 25, in index
    if currentUser['images'][0]:
       ~~~~~~~~~~~^^^^^^^^^^
KeyError: 'images'
Internal Server Error: /
Traceback (most recent call last):
  File "/usr/local/lib/python3.13/site-packages/django/core/handlers/exception.py", line 55, in inner
    response = get_response(request)
  File "/usr/local/lib/python3.13/site-packages/django/core/handlers/base.py", line 197, in _get_response
    response = wrapped_callback(request, *callback_args, **callback_kwargs)
  File "/backend/backend/views.py", line 25, in index
    if currentUser['images'][0]:
       ~~~~~~~~~~~^^^^^^^^^^
KeyError: 'images'
Internal Server Error: /
Traceback (most recent call last):
  File "/usr/local/lib/python3.13/site-packages/django/core/handlers/exception.py", line 55, in inner
    response = get_response(request)
  File "/usr/local/lib/python3.13/site-packages/django/core/handlers/base.py", line 197, in _get_response
    response = wrapped_callback(request, *callback_args, **callback_kwargs)
  File "/backend/backend/views.py", line 25, in index
    if currentUser['images'][0]:
       ~~~~~~~~~~~^^^^^^^^^^
KeyError: 'images'
Internal Server Error: /
Traceback (most recent call last):
  File "/usr/local/lib/python3.13/site-packages/django/core/handlers/exception.py", line 55, in inner
    response = get_response(request)
  File "/usr/local/lib/python3.13/site-packages/django/core/handlers/base.py", line 197, in _get_response
    response = wrapped_callback(request, *callback_args, **callback_kwargs)
  File "/backend/backend/views.py", line 25, in index
    if currentUser['images'][0]:
       ~~~~~~~~~~~^^^^^^^^^^
KeyError: 'images'
Internal Server Error: /
Traceback (most recent call last):
  File "/usr/local/lib/python3.13/site-packages/django/core/handlers/exception.py", line 55, in inner
    response = get_response(request)
  File "/usr/local/lib/python3.13/site-packages/django/core/handlers/base.py", line 197, in _get_response
    response = wrapped_callback(request, *callback_args, **callback_kwargs)
  File "/backend/backend/views.py", line 25, in index
    if currentUser['images'][0]:
       ~~~~~~~~~~~^^^^^^^^^^
KeyError: 'images'
Internal Server Error: /
Traceback (most recent call last):
  File "/usr/local/lib/python3.13/site-packages/django/core/handlers/exception.py", line 55, in inner
    response = get_response(request)
  File "/usr/local/lib/python3.13/site-packages/django/core/handlers/base.py", line 197, in _get_response
    response = wrapped_callback(request, *callback_args, **callback_kwargs)
  File "/backend/backend/views.py", line 25, in index
    if currentUser['images'][0]:
       ~~~~~~~~~~~^^^^^^^^^^
KeyError: 'images'
Internal Server Error: /
Traceback (most recent call last):
  File "/usr/local/lib/python3.13/site-packages/django/core/handlers/exception.py", line 55, in inner
    response = get_response(request)
  File "/usr/local/lib/python3.13/site-packages/django/core/handlers/base.py", line 197, in _get_response
    response = wrapped_callback(request, *callback_args, **callback_kwargs)
  File "/backend/backend/views.py", line 25, in index
    if currentUser['images'][0]:
       ~~~~~~~~~~~^^^^^^^^^^
KeyError: 'images'
Internal Server Error: /
Traceback (most recent call last):
  File "/usr/local/lib/python3.13/site-packages/django/core/handlers/exception.py", line 55, in inner
    response = get_response(request)
  File "/usr/local/lib/python3.13/site-packages/django/core/handlers/base.py", line 197, in _get_response
    response = wrapped_callback(request, *callback_args, **callback_kwargs)
  File "/backend/backend/views.py", line 25, in index
    if currentUser['images'][0]:
       ~~~~~~~~~~~^^^^^^^^^^
KeyError: 'images'
Internal Server Error: /
Traceback (most recent call last):
  File "/usr/local/lib/python3.13/site-packages/django/core/handlers/exception.py", line 55, in inner
    response = get_response(request)
  File "/usr/local/lib/python3.13/site-packages/django/core/handlers/base.py", line 197, in _get_response
    response = wrapped_callback(request, *callback_args, **callback_kwargs)
  File "/backend/backend/views.py", line 25, in index
    if currentUser['images'][0]:
       ~~~~~~~~~~~^^^^^^^^^^
KeyError: 'images'
Internal Server Error: /
Traceback (most recent call last):
  File "/usr/local/lib/python3.13/site-packages/django/core/handlers/exception.py", line 55, in inner
    response = get_response(request)
  File "/usr/local/lib/python3.13/site-packages/django/core/handlers/base.py", line 197, in _get_response
    response = wrapped_callback(request, *callback_args, **callback_kwargs)
  File "/backend/backend/views.py", line 25, in index
    if currentUser['images'][0]:
       ~~~~~~~~~~~^^^^^^^^^^
KeyError: 'images'
Internal Server Error: /
Traceback (most recent call last):
  File "/usr/local/lib/python3.13/site-packages/django/core/handlers/exception.py", line 55, in inner
    response = get_response(request)
  File "/usr/local/lib/python3.13/site-packages/django/core/handlers/base.py", line 197, in _get_response
    response = wrapped_callback(request, *callback_args, **callback_kwargs)
  File "/backend/backend/views.py", line 25, in index
    if currentUser['images'][0]:
       ~~~~~~~~~~~^^^^^^^^^^
KeyError: 'images'
Internal Server Error: /
Traceback (most recent call last):
  File "/usr/local/lib/python3.13/site-packages/django/core/handlers/exception.py", line 55, in inner
    response = get_response(request)
  File "/usr/local/lib/python3.13/site-packages/django/core/handlers/base.py", line 197, in _get_response
    response = wrapped_callback(request, *callback_args, **callback_kwargs)
  File "/backend/backend/views.py", line 25, in index
    if currentUser['images'][0]:
       ~~~~~~~~~~~^^^^^^^^^^
KeyError: 'images'
Internal Server Error: /
Traceback (most recent call last):
  File "/usr/local/lib/python3.13/site-packages/django/core/handlers/exception.py", line 55, in inner
    response = get_response(request)
  File "/usr/local/lib/python3.13/site-packages/django/core/handlers/base.py", line 197, in _get_response
    response = wrapped_callback(request, *callback_args, **callback_kwargs)
  File "/backend/backend/views.py", line 25, in index
    if currentUser['images'][0]:
       ~~~~~~~~~~~^^^^^^^^^^
KeyError: 'images'
Internal Server Error: /
Traceback (most recent call last):
  File "/usr/local/lib/python3.13/site-packages/django/core/handlers/exception.py", line 55, in inner
    response = get_response(request)
  File "/usr/local/lib/python3.13/site-packages/django/core/handlers/base.py", line 197, in _get_response
    response = wrapped_callback(request, *callback_args, **callback_kwargs)
  File "/backend/backend/views.py", line 25, in index
    if currentUser['images'][0]:
       ~~~~~~~~~~~^^^^^^^^^^
KeyError: 'images'
Internal Server Error: /
Traceback (most recent call last):
  File "/usr/local/lib/python3.13/site-packages/django/core/handlers/exception.py", line 55, in inner
    response = get_response(request)
  File "/usr/local/lib/python3.13/site-packages/django/core/handlers/base.py", line 197, in _get_response
    response = wrapped_callback(request, *callback_args, **callback_kwargs)
  File "/backend/backend/views.py", line 25, in index
    if currentUser['images'][0]:
       ~~~~~~~~~~~^^^^^^^^^^
KeyError: 'images'
Internal Server Error: /
Traceback (most recent call last):
  File "/usr/local/lib/python3.13/site-packages/django/core/handlers/exception.py", line 55, in inner
    response = get_response(request)
  File "/usr/local/lib/python3.13/site-packages/django/core/handlers/base.py", line 197, in _get_response
    response = wrapped_callback(request, *callback_args, **callback_kwargs)
  File "/backend/backend/views.py", line 25, in index
    if currentUser['images'][0]:
       ~~~~~~~~~~~^^^^^^^^^^
KeyError: 'images'
Internal Server Error: /
Traceback (most recent call last):
  File "/usr/local/lib/python3.13/site-packages/django/core/handlers/exception.py", line 55, in inner
    response = get_response(request)
  File "/usr/local/lib/python3.13/site-packages/django/core/handlers/base.py", line 197, in _get_response
    response = wrapped_callback(request, *callback_args, **callback_kwargs)
  File "/backend/backend/views.py", line 25, in index
    if currentUser['images'][0]:
       ~~~~~~~~~~~^^^^^^^^^^
KeyError: 'images'
Internal Server Error: /
Traceback (most recent call last):
  File "/usr/local/lib/python3.13/site-packages/django/core/handlers/exception.py", line 55, in inner
    response = get_response(request)
  File "/usr/local/lib/python3.13/site-packages/django/core/handlers/base.py", line 197, in _get_response
    response = wrapped_callback(request, *callback_args, **callback_kwargs)
  File "/backend/backend/views.py", line 25, in index
    if currentUser['images'][0]:
       ~~~~~~~~~~~^^^^^^^^^^
KeyError: 'images'
Internal Server Error: /
Traceback (most recent call last):
  File "/usr/local/lib/python3.13/site-packages/django/core/handlers/exception.py", line 55, in inner
    response = get_response(request)
  File "/usr/local/lib/python3.13/site-packages/django/core/handlers/base.py", line 197, in _get_response
    response = wrapped_callback(request, *callback_args, **callback_kwargs)
  File "/backend/backend/views.py", line 25, in index
    if currentUser['images'][0]:
       ~~~~~~~~~~~^^^^^^^^^^
KeyError: 'images'
Internal Server Error: /
Traceback (most recent call last):
  File "/usr/local/lib/python3.13/site-packages/django/core/handlers/exception.py", line 55, in inner
    response = get_response(request)
  File "/usr/local/lib/python3.13/site-packages/django/core/handlers/base.py", line 197, in _get_response
    response = wrapped_callback(request, *callback_args, **callback_kwargs)
  File "/backend/backend/views.py", line 25, in index
    if currentUser['images'][0]:
       ~~~~~~~~~~~^^^^^^^^^^
KeyError: 'images'
Internal Server Error: /
Traceback (most recent call last):
  File "/usr/local/lib/python3.13/site-packages/django/core/handlers/exception.py", line 55, in inner
    response = get_response(request)
  File "/usr/local/lib/python3.13/site-packages/django/core/handlers/base.py", line 197, in _get_response
    response = wrapped_callback(request, *callback_args, **callback_kwargs)
  File "/backend/backend/views.py", line 25, in index
    if currentUser['images'][0]:
       ~~~~~~~~~~~^^^^^^^^^^
KeyError: 'images'
Internal Server Error: /
Traceback (most recent call last):
  File "/usr/local/lib/python3.13/site-packages/django/core/handlers/exception.py", line 55, in inner
    response = get_response(request)
  File "/usr/local/lib/python3.13/site-packages/django/core/handlers/base.py", line 197, in _get_response
    response = wrapped_callback(request, *callback_args, **callback_kwargs)
  File "/backend/backend/views.py", line 25, in index
    if currentUser['images'][0]:
       ~~~~~~~~~~~^^^^^^^^^^
KeyError: 'images'
Internal Server Error: /
Traceback (most recent call last):
  File "/usr/local/lib/python3.13/site-packages/django/core/handlers/exception.py", line 55, in inner
    response = get_response(request)
  File "/usr/local/lib/python3.13/site-packages/django/core/handlers/base.py", line 197, in _get_response
    response = wrapped_callback(request, *callback_args, **callback_kwargs)
  File "/backend/backend/views.py", line 25, in index
    if currentUser['images'][0]:
       ~~~~~~~~~~~^^^^^^^^^^
KeyError: 'images'
Internal Server Error: /
Traceback (most recent call last):
  File "/usr/local/lib/python3.13/site-packages/django/core/handlers/exception.py", line 55, in inner
    response = get_response(request)
  File "/usr/local/lib/python3.13/site-packages/django/core/handlers/base.py", line 197, in _get_response
    response = wrapped_callback(request, *callback_args, **callback_kwargs)
  File "/backend/backend/views.py", line 25, in index
    if currentUser['images'][0]:
       ~~~~~~~~~~~^^^^^^^^^^
KeyError: 'images'
Internal Server Error: /
Traceback (most recent call last):
  File "/usr/local/lib/python3.13/site-packages/django/core/handlers/exception.py", line 55, in inner
    response = get_response(request)
  File "/usr/local/lib/python3.13/site-packages/django/core/handlers/base.py", line 197, in _get_response
    response = wrapped_callback(request, *callback_args, **callback_kwargs)
  File "/backend/backend/views.py", line 25, in index
    if currentUser['images'][0]:
       ~~~~~~~~~~~^^^^^^^^^^
KeyError: 'images'
Internal Server Error: /
Traceback (most recent call last):
  File "/usr/local/lib/python3.13/site-packages/django/core/handlers/exception.py", line 55, in inner
    response = get_response(request)
  File "/usr/local/lib/python3.13/site-packages/django/core/handlers/base.py", line 197, in _get_response
    response = wrapped_callback(request, *callback_args, **callback_kwargs)
  File "/backend/backend/views.py", line 25, in index
    if currentUser['images'][0]:
       ~~~~~~~~~~~^^^^^^^^^^
KeyError: 'images'
Internal Server Error: /
Traceback (most recent call last):
  File "/usr/local/lib/python3.13/site-packages/django/core/handlers/exception.py", line 55, in inner
    response = get_response(request)
  File "/usr/local/lib/python3.13/site-packages/django/core/handlers/base.py", line 197, in _get_response
    response = wrapped_callback(request, *callback_args, **callback_kwargs)
  File "/backend/backend/views.py", line 25, in index
    if currentUser['images'][0]:
       ~~~~~~~~~~~^^^^^^^^^^
KeyError: 'images'
Internal Server Error: /
Traceback (most recent call last):
  File "/usr/local/lib/python3.13/site-packages/django/core/handlers/exception.py", line 55, in inner
    response = get_response(request)
  File "/usr/local/lib/python3.13/site-packages/django/core/handlers/base.py", line 197, in _get_response
    response = wrapped_callback(request, *callback_args, **callback_kwargs)
  File "/backend/backend/views.py", line 25, in index
    if currentUser['images'][0]:
       ~~~~~~~~~~~^^^^^^^^^^
KeyError: 'images'
Internal Server Error: /
Traceback (most recent call last):
  File "/usr/local/lib/python3.13/site-packages/django/core/handlers/exception.py", line 55, in inner
    response = get_response(request)
  File "/usr/local/lib/python3.13/site-packages/django/core/handlers/base.py", line 197, in _get_response
    response = wrapped_callback(request, *callback_args, **callback_kwargs)
  File "/backend/backend/views.py", line 25, in index
    if currentUser['images'][0]:
       ~~~~~~~~~~~^^^^^^^^^^
KeyError: 'images'
Internal Server Error: /
Traceback (most recent call last):
  File "/usr/local/lib/python3.13/site-packages/django/core/handlers/exception.py", line 55, in inner
    response = get_response(request)
  File "/usr/local/lib/python3.13/site-packages/django/core/handlers/base.py", line 197, in _get_response
    response = wrapped_callback(request, *callback_args, **callback_kwargs)
  File "/backend/backend/views.py", line 25, in index
    if currentUser['images'][0]:
       ~~~~~~~~~~~^^^^^^^^^^
KeyError: 'images'
Internal Server Error: /
Traceback (most recent call last):
  File "/usr/local/lib/python3.13/site-packages/django/core/handlers/exception.py", line 55, in inner
    response = get_response(request)
  File "/usr/local/lib/python3.13/site-packages/django/core/handlers/base.py", line 197, in _get_response
    response = wrapped_callback(request, *callback_args, **callback_kwargs)
  File "/backend/backend/views.py", line 25, in index
    if currentUser['images'][0]:
       ~~~~~~~~~~~^^^^^^^^^^
KeyError: 'images'
Internal Server Error: /
Traceback (most recent call last):
  File "/usr/local/lib/python3.13/site-packages/django/core/handlers/exception.py", line 55, in inner
    response = get_response(request)
  File "/usr/local/lib/python3.13/site-packages/django/core/handlers/base.py", line 197, in _get_response
    response = wrapped_callback(request, *callback_args, **callback_kwargs)
  File "/backend/backend/views.py", line 25, in index
    if currentUser['images'][0]:
       ~~~~~~~~~~~^^^^^^^^^^
KeyError: 'images'
Internal Server Error: /
Traceback (most recent call last):
  File "/usr/local/lib/python3.13/site-packages/django/core/handlers/exception.py", line 55, in inner
    response = get_response(request)
  File "/usr/local/lib/python3.13/site-packages/django/core/handlers/base.py", line 197, in _get_response
    response = wrapped_callback(request, *callback_args, **callback_kwargs)
  File "/backend/backend/views.py", line 25, in index
    if currentUser['images'][0]:
       ~~~~~~~~~~~^^^^^^^^^^
KeyError: 'images'
Internal Server Error: /
Traceback (most recent call last):
  File "/usr/local/lib/python3.13/site-packages/django/core/handlers/exception.py", line 55, in inner
    response = get_response(request)
  File "/usr/local/lib/python3.13/site-packages/django/core/handlers/base.py", line 197, in _get_response
    response = wrapped_callback(request, *callback_args, **callback_kwargs)
  File "/backend/backend/views.py", line 25, in index
    if currentUser['images'][0]:
       ~~~~~~~~~~~^^^^^^^^^^
KeyError: 'images'
Internal Server Error: /
Traceback (most recent call last):
  File "/usr/local/lib/python3.13/site-packages/django/core/handlers/exception.py", line 55, in inner
    response = get_response(request)
  File "/usr/local/lib/python3.13/site-packages/django/core/handlers/base.py", line 197, in _get_response
    response = wrapped_callback(request, *callback_args, **callback_kwargs)
  File "/backend/backend/views.py", line 25, in index
    if currentUser['images'][0]:
       ~~~~~~~~~~~^^^^^^^^^^
KeyError: 'images'
Internal Server Error: /
Traceback (most recent call last):
  File "/usr/local/lib/python3.13/site-packages/django/core/handlers/exception.py", line 55, in inner
    response = get_response(request)
  File "/usr/local/lib/python3.13/site-packages/django/core/handlers/base.py", line 197, in _get_response
    response = wrapped_callback(request, *callback_args, **callback_kwargs)
  File "/backend/backend/views.py", line 25, in index
    if currentUser['images'][0]:
       ~~~~~~~~~~~^^^^^^^^^^
KeyError: 'images'
Internal Server Error: /
Traceback (most recent call last):
  File "/usr/local/lib/python3.13/site-packages/django/core/handlers/exception.py", line 55, in inner
    response = get_response(request)
  File "/usr/local/lib/python3.13/site-packages/django/core/handlers/base.py", line 197, in _get_response
    response = wrapped_callback(request, *callback_args, **callback_kwargs)
  File "/backend/backend/views.py", line 25, in index
    if currentUser['images'][0]:
       ~~~~~~~~~~~^^^^^^^^^^
KeyError: 'images'
Internal Server Error: /
Traceback (most recent call last):
  File "/usr/local/lib/python3.13/site-packages/django/core/handlers/exception.py", line 55, in inner
    response = get_response(request)
  File "/usr/local/lib/python3.13/site-packages/django/core/handlers/base.py", line 197, in _get_response
    response = wrapped_callback(request, *callback_args, **callback_kwargs)
  File "/backend/backend/views.py", line 25, in index
    if currentUser['images'][0]:
       ~~~~~~~~~~~^^^^^^^^^^
KeyError: 'images'
Internal Server Error: /
Traceback (most recent call last):
  File "/usr/local/lib/python3.13/site-packages/django/core/handlers/exception.py", line 55, in inner
    response = get_response(request)
  File "/usr/local/lib/python3.13/site-packages/django/core/handlers/base.py", line 197, in _get_response
    response = wrapped_callback(request, *callback_args, **callback_kwargs)
  File "/backend/backend/views.py", line 25, in index
    if currentUser['images'][0]:
       ~~~~~~~~~~~^^^^^^^^^^
KeyError: 'images'
Internal Server Error: /
Traceback (most recent call last):
  File "/usr/local/lib/python3.13/site-packages/django/core/handlers/exception.py", line 55, in inner
    response = get_response(request)
  File "/usr/local/lib/python3.13/site-packages/django/core/handlers/base.py", line 197, in _get_response
    response = wrapped_callback(request, *callback_args, **callback_kwargs)
  File "/backend/backend/views.py", line 25, in index
    if currentUser['images'][0]:
       ~~~~~~~~~~~^^^^^^^^^^
KeyError: 'images'
Internal Server Error: /
Traceback (most recent call last):
  File "/usr/local/lib/python3.13/site-packages/django/core/handlers/exception.py", line 55, in inner
    response = get_response(request)
  File "/usr/local/lib/python3.13/site-packages/django/core/handlers/base.py", line 197, in _get_response
    response = wrapped_callback(request, *callback_args, **callback_kwargs)
  File "/backend/backend/views.py", line 25, in index
    if currentUser['images'][0]:
       ~~~~~~~~~~~^^^^^^^^^^
KeyError: 'images'
Internal Server Error: /
Traceback (most recent call last):
  File "/usr/local/lib/python3.13/site-packages/django/core/handlers/exception.py", line 55, in inner
    response = get_response(request)
  File "/usr/local/lib/python3.13/site-packages/django/core/handlers/base.py", line 197, in _get_response
    response = wrapped_callback(request, *callback_args, **callback_kwargs)
  File "/backend/backend/views.py", line 25, in index
    if currentUser['images'][0]:
       ~~~~~~~~~~~^^^^^^^^^^
KeyError: 'images'
Internal Server Error: /
Traceback (most recent call last):
  File "/usr/local/lib/python3.13/site-packages/django/core/handlers/exception.py", line 55, in inner
    response = get_response(request)
  File "/usr/local/lib/python3.13/site-packages/django/core/handlers/base.py", line 197, in _get_response
    response = wrapped_callback(request, *callback_args, **callback_kwargs)
  File "/backend/backend/views.py", line 25, in index
    if currentUser['images'][0]:
       ~~~~~~~~~~~^^^^^^^^^^
KeyError: 'images'
Internal Server Error: /
Traceback (most recent call last):
  File "/usr/local/lib/python3.13/site-packages/django/core/handlers/exception.py", line 55, in inner
    response = get_response(request)
  File "/usr/local/lib/python3.13/site-packages/django/core/handlers/base.py", line 197, in _get_response
    response = wrapped_callback(request, *callback_args, **callback_kwargs)
  File "/backend/backend/views.py", line 25, in index
    if currentUser['images'][0]:
       ~~~~~~~~~~~^^^^^^^^^^
KeyError: 'images'
