Watching for file changes with StatReloader
Watching for file changes with StatReloader
Watching for file changes with StatReloader
Watching for file changes with StatReloader
Watching for file changes with StatReloader
Watching for file changes with StatReloader
Watching for file changes with StatReloader
Watching for file changes with StatReloader
Watching for file changes with StatReloader
Watching for file changes with StatReloader
Watching for file changes with StatReloader
Watching for file changes with StatReloader
Internal Server Error: /
Traceback (most recent call last):
  File "/usr/local/lib/python3.13/site-packages/django/core/handlers/exception.py", line 55, in inner
    response = get_response(request)
  File "/usr/local/lib/python3.13/site-packages/django/core/handlers/base.py", line 197, in _get_response
    response = wrapped_callback(request, *callback_args, **callback_kwargs)
  File "/backend/backend/views.py", line 25, in index
    if currentUser['images'][0]:
       ~~~~~~~~~~~^^^^^^^^^^
KeyError: 'images'
Internal Server Error: /
Traceback (most recent call last):
  File "/usr/local/lib/python3.13/site-packages/django/core/handlers/exception.py", line 55, in inner
    response = get_response(request)
  File "/usr/local/lib/python3.13/site-packages/django/core/handlers/base.py", line 197, in _get_response
    response = wrapped_callback(request, *callback_args, **callback_kwargs)
  File "/backend/backend/views.py", line 25, in index
    if currentUser['images'][0]:
       ~~~~~~~~~~~^^^^^^^^^^
KeyError: 'images'
Internal Server Error: /
Traceback (most recent call last):
  File "/usr/local/lib/python3.13/site-packages/django/core/handlers/exception.py", line 55, in inner
    response = get_response(request)
  File "/usr/local/lib/python3.13/site-packages/django/core/handlers/base.py", line 197, in _get_response
    response = wrapped_callback(request, *callback_args, **callback_kwargs)
  File "/backend/backend/views.py", line 25, in index
    if currentUser['images'][0]:
       ~~~~~~~~~~~^^^^^^^^^^
KeyError: 'images'
Not Found: /getToken/
Internal Server Error: /
Traceback (most recent call last):
  File "/usr/local/lib/python3.13/site-packages/django/core/handlers/exception.py", line 55, in inner
    response = get_response(request)
  File "/usr/local/lib/python3.13/site-packages/django/core/handlers/base.py", line 197, in _get_response
    response = wrapped_callback(request, *callback_args, **callback_kwargs)
  File "/backend/backend/views.py", line 25, in index
    if currentUser['images'][0]:
       ~~~~~~~~~~~^^^^^^^^^^
KeyError: 'images'
Not Found: /getToken/
Internal Server Error: /
Traceback (most recent call last):
  File "/usr/local/lib/python3.13/site-packages/django/core/handlers/exception.py", line 55, in inner
    response = get_response(request)
  File "/usr/local/lib/python3.13/site-packages/django/core/handlers/base.py", line 197, in _get_response
    response = wrapped_callback(request, *callback_args, **callback_kwargs)
  File "/backend/backend/views.py", line 25, in index
    if currentUser['images'][0]:
       ~~~~~~~~~~~^^^^^^^^^^
KeyError: 'images'
Internal Server Error: /
Traceback (most recent call last):
  File "/usr/local/lib/python3.13/site-packages/django/core/handlers/exception.py", line 55, in inner
    response = get_response(request)
  File "/usr/local/lib/python3.13/site-packages/django/core/handlers/base.py", line 197, in _get_response
    response = wrapped_callback(request, *callback_args, **callback_kwargs)
  File "/backend/backend/views.py", line 25, in index
    if currentUser['images'][0]:
       ~~~~~~~~~~~^^^^^^^^^^
KeyError: 'images'
Internal Server Error: /
Traceback (most recent call last):
  File "/usr/local/lib/python3.13/site-packages/django/core/handlers/exception.py", line 55, in inner
    response = get_response(request)
  File "/usr/local/lib/python3.13/site-packages/django/core/handlers/base.py", line 197, in _get_response
    response = wrapped_callback(request, *callback_args, **callback_kwargs)
  File "/backend/backend/views.py", line 25, in index
    if currentUser['images'][0]:
       ~~~~~~~~~~~^^^^^^^^^^
KeyError: 'images'
Internal Server Error: /
Traceback (most recent call last):
  File "/usr/local/lib/python3.13/site-packages/django/core/handlers/exception.py", line 55, in inner
    response = get_response(request)
  File "/usr/local/lib/python3.13/site-packages/django/core/handlers/base.py", line 197, in _get_response
    response = wrapped_callback(request, *callback_args, **callback_kwargs)
  File "/backend/backend/views.py", line 25, in index
    if currentUser['images'][0]:
       ~~~~~~~~~~~^^^^^^^^^^
KeyError: 'images'
Internal Server Error: /
Traceback (most recent call last):
  File "/usr/local/lib/python3.13/site-packages/django/core/handlers/exception.py", line 55, in inner
    response = get_response(request)
  File "/usr/local/lib/python3.13/site-packages/django/core/handlers/base.py", line 197, in _get_response
    response = wrapped_callback(request, *callback_args, **callback_kwargs)
  File "/backend/backend/views.py", line 25, in index
    if currentUser['images'][0]:
       ~~~~~~~~~~~^^^^^^^^^^
KeyError: 'images'
Internal Server Error: /
Traceback (most recent call last):
  File "/usr/local/lib/python3.13/site-packages/django/core/handlers/exception.py", line 55, in inner
    response = get_response(request)
  File "/usr/local/lib/python3.13/site-packages/django/core/handlers/base.py", line 197, in _get_response
    response = wrapped_callback(request, *callback_args, **callback_kwargs)
  File "/backend/backend/views.py", line 25, in index
    if currentUser['images'][0]:
       ~~~~~~~~~~~^^^^^^^^^^
KeyError: 'images'
Internal Server Error: /
Traceback (most recent call last):
  File "/usr/local/lib/python3.13/site-packages/django/core/handlers/exception.py", line 55, in inner
    response = get_response(request)
  File "/usr/local/lib/python3.13/site-packages/django/core/handlers/base.py", line 197, in _get_response
    response = wrapped_callback(request, *callback_args, **callback_kwargs)
  File "/backend/backend/views.py", line 25, in index
    if currentUser['images'][0]:
       ~~~~~~~~~~~^^^^^^^^^^
KeyError: 'images'
Internal Server Error: /
Traceback (most recent call last):
  File "/usr/local/lib/python3.13/site-packages/django/core/handlers/exception.py", line 55, in inner
    response = get_response(request)
  File "/usr/local/lib/python3.13/site-packages/django/core/handlers/base.py", line 197, in _get_response
    response = wrapped_callback(request, *callback_args, **callback_kwargs)
  File "/backend/backend/views.py", line 25, in index
    if currentUser['images'][0]:
       ~~~~~~~~~~~^^^^^^^^^^
KeyError: 'images'
Internal Server Error: /
Traceback (most recent call last):
  File "/usr/local/lib/python3.13/site-packages/django/core/handlers/exception.py", line 55, in inner
    response = get_response(request)
  File "/usr/local/lib/python3.13/site-packages/django/core/handlers/base.py", line 197, in _get_response
    response = wrapped_callback(request, *callback_args, **callback_kwargs)
  File "/backend/backend/views.py", line 25, in index
    if currentUser['images'][0]:
       ~~~~~~~~~~~^^^^^^^^^^
KeyError: 'images'
Not Found: /getToken/
Internal Server Error: /
Traceback (most recent call last):
  File "/usr/local/lib/python3.13/site-packages/django/core/handlers/exception.py", line 55, in inner
    response = get_response(request)
  File "/usr/local/lib/python3.13/site-packages/django/core/handlers/base.py", line 197, in _get_response
    response = wrapped_callback(request, *callback_args, **callback_kwargs)
  File "/backend/backend/views.py", line 25, in index
    if currentUser['images'][0]:
       ~~~~~~~~~~~^^^^^^^^^^
KeyError: 'images'
Not Found: /getToken/
Internal Server Error: /
Traceback (most recent call last):
  File "/usr/local/lib/python3.13/site-packages/django/core/handlers/exception.py", line 55, in inner
    response = get_response(request)
  File "/usr/local/lib/python3.13/site-packages/django/core/handlers/base.py", line 197, in _get_response
    response = wrapped_callback(request, *callback_args, **callback_kwargs)
  File "/backend/backend/views.py", line 25, in index
    if currentUser['images'][0]:
       ~~~~~~~~~~~^^^^^^^^^^
KeyError: 'images'
Internal Server Error: /
Traceback (most recent call last):
  File "/usr/local/lib/python3.13/site-packages/django/core/handlers/exception.py", line 55, in inner
    response = get_response(request)
  File "/usr/local/lib/python3.13/site-packages/django/core/handlers/base.py", line 197, in _get_response
    response = wrapped_callback(request, *callback_args, **callback_kwargs)
  File "/backend/backend/views.py", line 25, in index
    if currentUser['images'][0]:
       ~~~~~~~~~~~^^^^^^^^^^
KeyError: 'images'
Internal Server Error: /
Traceback (most recent call last):
  File "/usr/local/lib/python3.13/site-packages/django/core/handlers/exception.py", line 55, in inner
    response = get_response(request)
  File "/usr/local/lib/python3.13/site-packages/django/core/handlers/base.py", line 197, in _get_response
    response = wrapped_callback(request, *callback_args, **callback_kwargs)
  File "/backend/backend/views.py", line 25, in index
    if currentUser['images'][0]:
       ~~~~~~~~~~~^^^^^^^^^^
KeyError: 'images'
Internal Server Error: /
Traceback (most recent call last):
  File "/usr/local/lib/python3.13/site-packages/django/core/handlers/exception.py", line 55, in inner
    response = get_response(request)
  File "/usr/local/lib/python3.13/site-packages/django/core/handlers/base.py", line 197, in _get_response
    response = wrapped_callback(request, *callback_args, **callback_kwargs)
  File "/backend/backend/views.py", line 25, in index
    if currentUser['images'][0]:
       ~~~~~~~~~~~^^^^^^^^^^
KeyError: 'images'
Internal Server Error: /
Traceback (most recent call last):
  File "/usr/local/lib/python3.13/site-packages/django/core/handlers/exception.py", line 55, in inner
    response = get_response(request)
  File "/usr/local/lib/python3.13/site-packages/django/core/handlers/base.py", line 197, in _get_response
    response = wrapped_callback(request, *callback_args, **callback_kwargs)
  File "/backend/backend/views.py", line 25, in index
    if currentUser['images'][0]:
       ~~~~~~~~~~~^^^^^^^^^^
KeyError: 'images'
Internal Server Error: /
Traceback (most recent call last):
  File "/usr/local/lib/python3.13/site-packages/django/core/handlers/exception.py", line 55, in inner
    response = get_response(request)
  File "/usr/local/lib/python3.13/site-packages/django/core/handlers/base.py", line 197, in _get_response
    response = wrapped_callback(request, *callback_args, **callback_kwargs)
  File "/backend/backend/views.py", line 25, in index
    if currentUser['images'][0]:
       ~~~~~~~~~~~^^^^^^^^^^
KeyError: 'images'
Internal Server Error: /
Traceback (most recent call last):
  File "/usr/local/lib/python3.13/site-packages/django/core/handlers/exception.py", line 55, in inner
    response = get_response(request)
  File "/usr/local/lib/python3.13/site-packages/django/core/handlers/base.py", line 197, in _get_response
    response = wrapped_callback(request, *callback_args, **callback_kwargs)
  File "/backend/backend/views.py", line 25, in index
    if currentUser['images'][0]:
       ~~~~~~~~~~~^^^^^^^^^^
KeyError: 'images'
Internal Server Error: /
Traceback (most recent call last):
  File "/usr/local/lib/python3.13/site-packages/django/core/handlers/exception.py", line 55, in inner
    response = get_response(request)
  File "/usr/local/lib/python3.13/site-packages/django/core/handlers/base.py", line 197, in _get_response
    response = wrapped_callback(request, *callback_args, **callback_kwargs)
  File "/backend/backend/views.py", line 25, in index
    if currentUser['images'][0]:
       ~~~~~~~~~~~^^^^^^^^^^
KeyError: 'images'
Internal Server Error: /
Traceback (most recent call last):
  File "/usr/local/lib/python3.13/site-packages/django/core/handlers/exception.py", line 55, in inner
    response = get_response(request)
  File "/usr/local/lib/python3.13/site-packages/django/core/handlers/base.py", line 197, in _get_response
    response = wrapped_callback(request, *callback_args, **callback_kwargs)
  File "/backend/backend/views.py", line 25, in index
    if currentUser['images'][0]:
       ~~~~~~~~~~~^^^^^^^^^^
KeyError: 'images'
Internal Server Error: /
Traceback (most recent call last):
  File "/usr/local/lib/python3.13/site-packages/django/core/handlers/exception.py", line 55, in inner
    response = get_response(request)
  File "/usr/local/lib/python3.13/site-packages/django/core/handlers/base.py", line 197, in _get_response
    response = wrapped_callback(request, *callback_args, **callback_kwargs)
  File "/backend/backend/views.py", line 25, in index
    if currentUser['images'][0]:
       ~~~~~~~~~~~^^^^^^^^^^
KeyError: 'images'
Internal Server Error: /
Traceback (most recent call last):
  File "/usr/local/lib/python3.13/site-packages/django/core/handlers/exception.py", line 55, in inner
    response = get_response(request)
  File "/usr/local/lib/python3.13/site-packages/django/core/handlers/base.py", line 197, in _get_response
    response = wrapped_callback(request, *callback_args, **callback_kwargs)
  File "/backend/backend/views.py", line 25, in index
    if currentUser['images'][0]:
       ~~~~~~~~~~~^^^^^^^^^^
KeyError: 'images'
Internal Server Error: /
Traceback (most recent call last):
  File "/usr/local/lib/python3.13/site-packages/django/core/handlers/exception.py", line 55, in inner
    response = get_response(request)
  File "/usr/local/lib/python3.13/site-packages/django/core/handlers/base.py", line 197, in _get_response
    response = wrapped_callback(request, *callback_args, **callback_kwargs)
  File "/backend/backend/views.py", line 25, in index
    if currentUser['images'][0]:
       ~~~~~~~~~~~^^^^^^^^^^
KeyError: 'images'
Internal Server Error: /
Traceback (most recent call last):
  File "/usr/local/lib/python3.13/site-packages/django/core/handlers/exception.py", line 55, in inner
    response = get_response(request)
  File "/usr/local/lib/python3.13/site-packages/django/core/handlers/base.py", line 197, in _get_response
    response = wrapped_callback(request, *callback_args, **callback_kwargs)
  File "/backend/backend/views.py", line 25, in index
    if currentUser['images'][0]:
       ~~~~~~~~~~~^^^^^^^^^^
KeyError: 'images'
Internal Server Error: /
Traceback (most recent call last):
  File "/usr/local/lib/python3.13/site-packages/django/core/handlers/exception.py", line 55, in inner
    response = get_response(request)
  File "/usr/local/lib/python3.13/site-packages/django/core/handlers/base.py", line 197, in _get_response
    response = wrapped_callback(request, *callback_args, **callback_kwargs)
  File "/backend/backend/views.py", line 25, in index
    if currentUser['images'][0]:
       ~~~~~~~~~~~^^^^^^^^^^
KeyError: 'images'
Internal Server Error: /
Traceback (most recent call last):
  File "/usr/local/lib/python3.13/site-packages/django/core/handlers/exception.py", line 55, in inner
    response = get_response(request)
  File "/usr/local/lib/python3.13/site-packages/django/core/handlers/base.py", line 197, in _get_response
    response = wrapped_callback(request, *callback_args, **callback_kwargs)
  File "/backend/backend/views.py", line 25, in index
    if currentUser['images'][0]:
       ~~~~~~~~~~~^^^^^^^^^^
KeyError: 'images'
Internal Server Error: /
Traceback (most recent call last):
  File "/usr/local/lib/python3.13/site-packages/django/core/handlers/exception.py", line 55, in inner
    response = get_response(request)
  File "/usr/local/lib/python3.13/site-packages/django/core/handlers/base.py", line 197, in _get_response
    response = wrapped_callback(request, *callback_args, **callback_kwargs)
  File "/backend/backend/views.py", line 25, in index
    if currentUser['images'][0]:
       ~~~~~~~~~~~^^^^^^^^^^
KeyError: 'images'
Internal Server Error: /
Traceback (most recent call last):
  File "/usr/local/lib/python3.13/site-packages/django/core/handlers/exception.py", line 55, in inner
    response = get_response(request)
  File "/usr/local/lib/python3.13/site-packages/django/core/handlers/base.py", line 197, in _get_response
    response = wrapped_callback(request, *callback_args, **callback_kwargs)
  File "/backend/backend/views.py", line 25, in index
    if currentUser['images'][0]:
       ~~~~~~~~~~~^^^^^^^^^^
KeyError: 'images'
Internal Server Error: /
Traceback (most recent call last):
  File "/usr/local/lib/python3.13/site-packages/django/core/handlers/exception.py", line 55, in inner
    response = get_response(request)
  File "/usr/local/lib/python3.13/site-packages/django/core/handlers/base.py", line 197, in _get_response
    response = wrapped_callback(request, *callback_args, **callback_kwargs)
  File "/backend/backend/views.py", line 25, in index
    if currentUser['images'][0]:
       ~~~~~~~~~~~^^^^^^^^^^
KeyError: 'images'
Internal Server Error: /
Traceback (most recent call last):
  File "/usr/local/lib/python3.13/site-packages/django/core/handlers/exception.py", line 55, in inner
    response = get_response(request)
  File "/usr/local/lib/python3.13/site-packages/django/core/handlers/base.py", line 197, in _get_response
    response = wrapped_callback(request, *callback_args, **callback_kwargs)
  File "/backend/backend/views.py", line 25, in index
    if currentUser['images'][0]:
       ~~~~~~~~~~~^^^^^^^^^^
KeyError: 'images'
Internal Server Error: /
Traceback (most recent call last):
  File "/usr/local/lib/python3.13/site-packages/django/core/handlers/exception.py", line 55, in inner
    response = get_response(request)
  File "/usr/local/lib/python3.13/site-packages/django/core/handlers/base.py", line 197, in _get_response
    response = wrapped_callback(request, *callback_args, **callback_kwargs)
  File "/backend/backend/views.py", line 25, in index
    if currentUser['images'][0]:
       ~~~~~~~~~~~^^^^^^^^^^
KeyError: 'images'
Internal Server Error: /
Traceback (most recent call last):
  File "/usr/local/lib/python3.13/site-packages/django/core/handlers/exception.py", line 55, in inner
    response = get_response(request)
  File "/usr/local/lib/python3.13/site-packages/django/core/handlers/base.py", line 197, in _get_response
    response = wrapped_callback(request, *callback_args, **callback_kwargs)
  File "/backend/backend/views.py", line 25, in index
    if currentUser['images'][0]:
       ~~~~~~~~~~~^^^^^^^^^^
KeyError: 'images'
Internal Server Error: /
Traceback (most recent call last):
  File "/usr/local/lib/python3.13/site-packages/django/core/handlers/exception.py", line 55, in inner
    response = get_response(request)
  File "/usr/local/lib/python3.13/site-packages/django/core/handlers/base.py", line 197, in _get_response
    response = wrapped_callback(request, *callback_args, **callback_kwargs)
  File "/backend/backend/views.py", line 25, in index
    if currentUser['images'][0]:
       ~~~~~~~~~~~^^^^^^^^^^
KeyError: 'images'
Internal Server Error: /
Traceback (most recent call last):
  File "/usr/local/lib/python3.13/site-packages/django/core/handlers/exception.py", line 55, in inner
    response = get_response(request)
  File "/usr/local/lib/python3.13/site-packages/django/core/handlers/base.py", line 197, in _get_response
    response = wrapped_callback(request, *callback_args, **callback_kwargs)
  File "/backend/backend/views.py", line 25, in index
    if currentUser['images'][0]:
       ~~~~~~~~~~~^^^^^^^^^^
KeyError: 'images'
Internal Server Error: /
Traceback (most recent call last):
  File "/usr/local/lib/python3.13/site-packages/django/core/handlers/exception.py", line 55, in inner
    response = get_response(request)
  File "/usr/local/lib/python3.13/site-packages/django/core/handlers/base.py", line 197, in _get_response
    response = wrapped_callback(request, *callback_args, **callback_kwargs)
  File "/backend/backend/views.py", line 25, in index
    if currentUser['images'][0]:
       ~~~~~~~~~~~^^^^^^^^^^
KeyError: 'images'
Internal Server Error: /
Traceback (most recent call last):
  File "/usr/local/lib/python3.13/site-packages/django/core/handlers/exception.py", line 55, in inner
    response = get_response(request)
  File "/usr/local/lib/python3.13/site-packages/django/core/handlers/base.py", line 197, in _get_response
    response = wrapped_callback(request, *callback_args, **callback_kwargs)
  File "/backend/backend/views.py", line 25, in index
    if currentUser['images'][0]:
       ~~~~~~~~~~~^^^^^^^^^^
KeyError: 'images'
Internal Server Error: /
Traceback (most recent call last):
  File "/usr/local/lib/python3.13/site-packages/django/core/handlers/exception.py", line 55, in inner
    response = get_response(request)
  File "/usr/local/lib/python3.13/site-packages/django/core/handlers/base.py", line 197, in _get_response
    response = wrapped_callback(request, *callback_args, **callback_kwargs)
  File "/backend/backend/views.py", line 25, in index
    if currentUser['images'][0]:
       ~~~~~~~~~~~^^^^^^^^^^
KeyError: 'images'
Internal Server Error: /
Traceback (most recent call last):
  File "/usr/local/lib/python3.13/site-packages/django/core/handlers/exception.py", line 55, in inner
    response = get_response(request)
  File "/usr/local/lib/python3.13/site-packages/django/core/handlers/base.py", line 197, in _get_response
    response = wrapped_callback(request, *callback_args, **callback_kwargs)
  File "/backend/backend/views.py", line 25, in index
    if currentUser['images'][0]:
       ~~~~~~~~~~~^^^^^^^^^^
KeyError: 'images'
Internal Server Error: /
Traceback (most recent call last):
  File "/usr/local/lib/python3.13/site-packages/django/core/handlers/exception.py", line 55, in inner
    response = get_response(request)
  File "/usr/local/lib/python3.13/site-packages/django/core/handlers/base.py", line 197, in _get_response
    response = wrapped_callback(request, *callback_args, **callback_kwargs)
  File "/backend/backend/views.py", line 25, in index
    if currentUser['images'][0]:
       ~~~~~~~~~~~^^^^^^^^^^
KeyError: 'images'
Internal Server Error: /
Traceback (most recent call last):
  File "/usr/local/lib/python3.13/site-packages/django/core/handlers/exception.py", line 55, in inner
    response = get_response(request)
  File "/usr/local/lib/python3.13/site-packages/django/core/handlers/base.py", line 197, in _get_response
    response = wrapped_callback(request, *callback_args, **callback_kwargs)
  File "/backend/backend/views.py", line 25, in index
    if currentUser['images'][0]:
       ~~~~~~~~~~~^^^^^^^^^^
KeyError: 'images'
Internal Server Error: /
Traceback (most recent call last):
  File "/usr/local/lib/python3.13/site-packages/django/core/handlers/exception.py", line 55, in inner
    response = get_response(request)
  File "/usr/local/lib/python3.13/site-packages/django/core/handlers/base.py", line 197, in _get_response
    response = wrapped_callback(request, *callback_args, **callback_kwargs)
  File "/backend/backend/views.py", line 25, in index
    if currentUser['images'][0]:
       ~~~~~~~~~~~^^^^^^^^^^
KeyError: 'images'
Internal Server Error: /
Traceback (most recent call last):
  File "/usr/local/lib/python3.13/site-packages/django/core/handlers/exception.py", line 55, in inner
    response = get_response(request)
  File "/usr/local/lib/python3.13/site-packages/django/core/handlers/base.py", line 197, in _get_response
    response = wrapped_callback(request, *callback_args, **callback_kwargs)
  File "/backend/backend/views.py", line 25, in index
    if currentUser['images'][0]:
       ~~~~~~~~~~~^^^^^^^^^^
KeyError: 'images'
Internal Server Error: /
Traceback (most recent call last):
  File "/usr/local/lib/python3.13/site-packages/django/core/handlers/exception.py", line 55, in inner
    response = get_response(request)
  File "/usr/local/lib/python3.13/site-packages/django/core/handlers/base.py", line 197, in _get_response
    response = wrapped_callback(request, *callback_args, **callback_kwargs)
  File "/backend/backend/views.py", line 25, in index
    if currentUser['images'][0]:
       ~~~~~~~~~~~^^^^^^^^^^
KeyError: 'images'
Internal Server Error: /
Traceback (most recent call last):
  File "/usr/local/lib/python3.13/site-packages/django/core/handlers/exception.py", line 55, in inner
    response = get_response(request)
  File "/usr/local/lib/python3.13/site-packages/django/core/handlers/base.py", line 197, in _get_response
    response = wrapped_callback(request, *callback_args, **callback_kwargs)
  File "/backend/backend/views.py", line 25, in index
    if currentUser['images'][0]:
       ~~~~~~~~~~~^^^^^^^^^^
KeyError: 'images'
Internal Server Error: /
Traceback (most recent call last):
  File "/usr/local/lib/python3.13/site-packages/django/core/handlers/exception.py", line 55, in inner
    response = get_response(request)
  File "/usr/local/lib/python3.13/site-packages/django/core/handlers/base.py", line 197, in _get_response
    response = wrapped_callback(request, *callback_args, **callback_kwargs)
  File "/backend/backend/views.py", line 25, in index
    if currentUser['images'][0]:
       ~~~~~~~~~~~^^^^^^^^^^
KeyError: 'images'
Internal Server Error: /
Traceback (most recent call last):
  File "/usr/local/lib/python3.13/site-packages/django/core/handlers/exception.py", line 55, in inner
    response = get_response(request)
  File "/usr/local/lib/python3.13/site-packages/django/core/handlers/base.py", line 197, in _get_response
    response = wrapped_callback(request, *callback_args, **callback_kwargs)
  File "/backend/backend/views.py", line 25, in index
    if currentUser['images'][0]:
       ~~~~~~~~~~~^^^^^^^^^^
KeyError: 'images'
Internal Server Error: /
Traceback (most recent call last):
  File "/usr/local/lib/python3.13/site-packages/django/core/handlers/exception.py", line 55, in inner
    response = get_response(request)
  File "/usr/local/lib/python3.13/site-packages/django/core/handlers/base.py", line 197, in _get_response
    response = wrapped_callback(request, *callback_args, **callback_kwargs)
  File "/backend/backend/views.py", line 25, in index
    if currentUser['images'][0]:
       ~~~~~~~~~~~^^^^^^^^^^
KeyError: 'images'
Internal Server Error: /
Traceback (most recent call last):
  File "/usr/local/lib/python3.13/site-packages/django/core/handlers/exception.py", line 55, in inner
    response = get_response(request)
  File "/usr/local/lib/python3.13/site-packages/django/core/handlers/base.py", line 197, in _get_response
    response = wrapped_callback(request, *callback_args, **callback_kwargs)
  File "/backend/backend/views.py", line 25, in index
    if currentUser['images'][0]:
       ~~~~~~~~~~~^^^^^^^^^^
KeyError: 'images'
Internal Server Error: /
Traceback (most recent call last):
  File "/usr/local/lib/python3.13/site-packages/django/core/handlers/exception.py", line 55, in inner
    response = get_response(request)
  File "/usr/local/lib/python3.13/site-packages/django/core/handlers/base.py", line 197, in _get_response
    response = wrapped_callback(request, *callback_args, **callback_kwargs)
  File "/backend/backend/views.py", line 25, in index
    if currentUser['images'][0]:
       ~~~~~~~~~~~^^^^^^^^^^
KeyError: 'images'
Internal Server Error: /
Traceback (most recent call last):
  File "/usr/local/lib/python3.13/site-packages/django/core/handlers/exception.py", line 55, in inner
    response = get_response(request)
  File "/usr/local/lib/python3.13/site-packages/django/core/handlers/base.py", line 197, in _get_response
    response = wrapped_callback(request, *callback_args, **callback_kwargs)
  File "/backend/backend/views.py", line 25, in index
    if currentUser['images'][0]:
       ~~~~~~~~~~~^^^^^^^^^^
KeyError: 'images'
Internal Server Error: /
Traceback (most recent call last):
  File "/usr/local/lib/python3.13/site-packages/django/core/handlers/exception.py", line 55, in inner
    response = get_response(request)
  File "/usr/local/lib/python3.13/site-packages/django/core/handlers/base.py", line 197, in _get_response
    response = wrapped_callback(request, *callback_args, **callback_kwargs)
  File "/backend/backend/views.py", line 25, in index
    if currentUser['images'][0]:
       ~~~~~~~~~~~^^^^^^^^^^
KeyError: 'images'
Internal Server Error: /
Traceback (most recent call last):
  File "/usr/local/lib/python3.13/site-packages/django/core/handlers/exception.py", line 55, in inner
    response = get_response(request)
  File "/usr/local/lib/python3.13/site-packages/django/core/handlers/base.py", line 197, in _get_response
    response = wrapped_callback(request, *callback_args, **callback_kwargs)
  File "/backend/backend/views.py", line 25, in index
    if currentUser['images'][0]:
       ~~~~~~~~~~~^^^^^^^^^^
KeyError: 'images'
Internal Server Error: /
Traceback (most recent call last):
  File "/usr/local/lib/python3.13/site-packages/django/core/handlers/exception.py", line 55, in inner
    response = get_response(request)
  File "/usr/local/lib/python3.13/site-packages/django/core/handlers/base.py", line 197, in _get_response
    response = wrapped_callback(request, *callback_args, **callback_kwargs)
  File "/backend/backend/views.py", line 25, in index
    if currentUser['images'][0]:
       ~~~~~~~~~~~^^^^^^^^^^
KeyError: 'images'
Internal Server Error: /
Traceback (most recent call last):
  File "/usr/local/lib/python3.13/site-packages/django/core/handlers/exception.py", line 55, in inner
    response = get_response(request)
  File "/usr/local/lib/python3.13/site-packages/django/core/handlers/base.py", line 197, in _get_response
    response = wrapped_callback(request, *callback_args, **callback_kwargs)
  File "/backend/backend/views.py", line 25, in index
    if currentUser['images'][0]:
       ~~~~~~~~~~~^^^^^^^^^^
KeyError: 'images'
Internal Server Error: /
Traceback (most recent call last):
  File "/usr/local/lib/python3.13/site-packages/django/core/handlers/exception.py", line 55, in inner
    response = get_response(request)
  File "/usr/local/lib/python3.13/site-packages/django/core/handlers/base.py", line 197, in _get_response
    response = wrapped_callback(request, *callback_args, **callback_kwargs)
  File "/backend/backend/views.py", line 25, in index
    if currentUser['images'][0]:
       ~~~~~~~~~~~^^^^^^^^^^
KeyError: 'images'
Internal Server Error: /
Traceback (most recent call last):
  File "/usr/local/lib/python3.13/site-packages/django/core/handlers/exception.py", line 55, in inner
    response = get_response(request)
  File "/usr/local/lib/python3.13/site-packages/django/core/handlers/base.py", line 197, in _get_response
    response = wrapped_callback(request, *callback_args, **callback_kwargs)
  File "/backend/backend/views.py", line 25, in index
    if currentUser['images'][0]:
       ~~~~~~~~~~~^^^^^^^^^^
KeyError: 'images'
Internal Server Error: /
Traceback (most recent call last):
  File "/usr/local/lib/python3.13/site-packages/django/core/handlers/exception.py", line 55, in inner
    response = get_response(request)
  File "/usr/local/lib/python3.13/site-packages/django/core/handlers/base.py", line 197, in _get_response
    response = wrapped_callback(request, *callback_args, **callback_kwargs)
  File "/backend/backend/views.py", line 25, in index
    if currentUser['images'][0]:
       ~~~~~~~~~~~^^^^^^^^^^
KeyError: 'images'
Internal Server Error: /
Traceback (most recent call last):
  File "/usr/local/lib/python3.13/site-packages/django/core/handlers/exception.py", line 55, in inner
    response = get_response(request)
  File "/usr/local/lib/python3.13/site-packages/django/core/handlers/base.py", line 197, in _get_response
    response = wrapped_callback(request, *callback_args, **callback_kwargs)
  File "/backend/backend/views.py", line 25, in index
    if currentUser['images'][0]:
       ~~~~~~~~~~~^^^^^^^^^^
KeyError: 'images'
Internal Server Error: /
Traceback (most recent call last):
  File "/usr/local/lib/python3.13/site-packages/django/core/handlers/exception.py", line 55, in inner
    response = get_response(request)
  File "/usr/local/lib/python3.13/site-packages/django/core/handlers/base.py", line 197, in _get_response
    response = wrapped_callback(request, *callback_args, **callback_kwargs)
  File "/backend/backend/views.py", line 25, in index
    if currentUser['images'][0]:
       ~~~~~~~~~~~^^^^^^^^^^
KeyError: 'images'
Internal Server Error: /
Traceback (most recent call last):
  File "/usr/local/lib/python3.13/site-packages/django/core/handlers/exception.py", line 55, in inner
    response = get_response(request)
  File "/usr/local/lib/python3.13/site-packages/django/core/handlers/base.py", line 197, in _get_response
    response = wrapped_callback(request, *callback_args, **callback_kwargs)
  File "/backend/backend/views.py", line 25, in index
    if currentUser['images'][0]:
       ~~~~~~~~~~~^^^^^^^^^^
KeyError: 'images'
Internal Server Error: /
Traceback (most recent call last):
  File "/usr/local/lib/python3.13/site-packages/django/core/handlers/exception.py", line 55, in inner
    response = get_response(request)
  File "/usr/local/lib/python3.13/site-packages/django/core/handlers/base.py", line 197, in _get_response
    response = wrapped_callback(request, *callback_args, **callback_kwargs)
  File "/backend/backend/views.py", line 25, in index
    if currentUser['images'][0]:
       ~~~~~~~~~~~^^^^^^^^^^
KeyError: 'images'
Internal Server Error: /
Traceback (most recent call last):
  File "/usr/local/lib/python3.13/site-packages/django/core/handlers/exception.py", line 55, in inner
    response = get_response(request)
  File "/usr/local/lib/python3.13/site-packages/django/core/handlers/base.py", line 197, in _get_response
    response = wrapped_callback(request, *callback_args, **callback_kwargs)
  File "/backend/backend/views.py", line 25, in index
    if currentUser['images'][0]:
       ~~~~~~~~~~~^^^^^^^^^^
KeyError: 'images'
Internal Server Error: /
Traceback (most recent call last):
  File "/usr/local/lib/python3.13/site-packages/django/core/handlers/exception.py", line 55, in inner
    response = get_response(request)
  File "/usr/local/lib/python3.13/site-packages/django/core/handlers/base.py", line 197, in _get_response
    response = wrapped_callback(request, *callback_args, **callback_kwargs)
  File "/backend/backend/views.py", line 25, in index
    if currentUser['images'][0]:
       ~~~~~~~~~~~^^^^^^^^^^
KeyError: 'images'
Internal Server Error: /
Traceback (most recent call last):
  File "/usr/local/lib/python3.13/site-packages/django/core/handlers/exception.py", line 55, in inner
    response = get_response(request)
  File "/usr/local/lib/python3.13/site-packages/django/core/handlers/base.py", line 197, in _get_response
    response = wrapped_callback(request, *callback_args, **callback_kwargs)
  File "/backend/backend/views.py", line 25, in index
    if currentUser['images'][0]:
       ~~~~~~~~~~~^^^^^^^^^^
KeyError: 'images'
Internal Server Error: /
Traceback (most recent call last):
  File "/usr/local/lib/python3.13/site-packages/django/core/handlers/exception.py", line 55, in inner
    response = get_response(request)
  File "/usr/local/lib/python3.13/site-packages/django/core/handlers/base.py", line 197, in _get_response
    response = wrapped_callback(request, *callback_args, **callback_kwargs)
  File "/backend/backend/views.py", line 25, in index
    if currentUser['images'][0]:
       ~~~~~~~~~~~^^^^^^^^^^
KeyError: 'images'
Internal Server Error: /
Traceback (most recent call last):
  File "/usr/local/lib/python3.13/site-packages/django/core/handlers/exception.py", line 55, in inner
    response = get_response(request)
  File "/usr/local/lib/python3.13/site-packages/django/core/handlers/base.py", line 197, in _get_response
    response = wrapped_callback(request, *callback_args, **callback_kwargs)
  File "/backend/backend/views.py", line 25, in index
    if currentUser['images'][0]:
       ~~~~~~~~~~~^^^^^^^^^^
KeyError: 'images'
Internal Server Error: /
Traceback (most recent call last):
  File "/usr/local/lib/python3.13/site-packages/django/core/handlers/exception.py", line 55, in inner
    response = get_response(request)
  File "/usr/local/lib/python3.13/site-packages/django/core/handlers/base.py", line 197, in _get_response
    response = wrapped_callback(request, *callback_args, **callback_kwargs)
  File "/backend/backend/views.py", line 25, in index
    if currentUser['images'][0]:
       ~~~~~~~~~~~^^^^^^^^^^
KeyError: 'images'
Internal Server Error: /
Traceback (most recent call last):
  File "/usr/local/lib/python3.13/site-packages/django/core/handlers/exception.py", line 55, in inner
    response = get_response(request)
  File "/usr/local/lib/python3.13/site-packages/django/core/handlers/base.py", line 197, in _get_response
    response = wrapped_callback(request, *callback_args, **callback_kwargs)
  File "/backend/backend/views.py", line 25, in index
    if currentUser['images'][0]:
       ~~~~~~~~~~~^^^^^^^^^^
KeyError: 'images'
Internal Server Error: /
Traceback (most recent call last):
  File "/usr/local/lib/python3.13/site-packages/django/core/handlers/exception.py", line 55, in inner
    response = get_response(request)
  File "/usr/local/lib/python3.13/site-packages/django/core/handlers/base.py", line 197, in _get_response
    response = wrapped_callback(request, *callback_args, **callback_kwargs)
  File "/backend/backend/views.py", line 25, in index
    if currentUser['images'][0]:
       ~~~~~~~~~~~^^^^^^^^^^
KeyError: 'images'
Internal Server Error: /
Traceback (most recent call last):
  File "/usr/local/lib/python3.13/site-packages/django/core/handlers/exception.py", line 55, in inner
    response = get_response(request)
  File "/usr/local/lib/python3.13/site-packages/django/core/handlers/base.py", line 197, in _get_response
    response = wrapped_callback(request, *callback_args, **callback_kwargs)
  File "/backend/backend/views.py", line 25, in index
    if currentUser['images'][0]:
       ~~~~~~~~~~~^^^^^^^^^^
KeyError: 'images'
Internal Server Error: /
Traceback (most recent call last):
  File "/usr/local/lib/python3.13/site-packages/django/core/handlers/exception.py", line 55, in inner
    response = get_response(request)
  File "/usr/local/lib/python3.13/site-packages/django/core/handlers/base.py", line 197, in _get_response
    response = wrapped_callback(request, *callback_args, **callback_kwargs)
  File "/backend/backend/views.py", line 25, in index
    if currentUser['images'][0]:
       ~~~~~~~~~~~^^^^^^^^^^
KeyError: 'images'
Internal Server Error: /
Traceback (most recent call last):
  File "/usr/local/lib/python3.13/site-packages/django/core/handlers/exception.py", line 55, in inner
    response = get_response(request)
  File "/usr/local/lib/python3.13/site-packages/django/core/handlers/base.py", line 197, in _get_response
    response = wrapped_callback(request, *callback_args, **callback_kwargs)
  File "/backend/backend/views.py", line 25, in index
    if currentUser['images'][0]:
       ~~~~~~~~~~~^^^^^^^^^^
KeyError: 'images'
Internal Server Error: /
Traceback (most recent call last):
  File "/usr/local/lib/python3.13/site-packages/django/core/handlers/exception.py", line 55, in inner
    response = get_response(request)
  File "/usr/local/lib/python3.13/site-packages/django/core/handlers/base.py", line 197, in _get_response
    response = wrapped_callback(request, *callback_args, **callback_kwargs)
  File "/backend/backend/views.py", line 25, in index
    if currentUser['images'][0]:
       ~~~~~~~~~~~^^^^^^^^^^
KeyError: 'images'
Watching for file changes with StatReloader
Internal Server Error: /
Traceback (most recent call last):
  File "/usr/local/lib/python3.13/site-packages/django/core/handlers/exception.py", line 55, in inner
    response = get_response(request)
  File "/usr/local/lib/python3.13/site-packages/django/core/handlers/base.py", line 197, in _get_response
    response = wrapped_callback(request, *callback_args, **callback_kwargs)
  File "/backend/backend/views.py", line 56, in index
    if currentUser['images'] and currentUser['images'][0]:
       ~~~~~~~~~~~^^^^^^^^^^
KeyError: 'images'
Internal Server Error: /
Traceback (most recent call last):
  File "/usr/local/lib/python3.13/site-packages/django/core/handlers/exception.py", line 55, in inner
    response = get_response(request)
  File "/usr/local/lib/python3.13/site-packages/django/core/handlers/base.py", line 197, in _get_response
    response = wrapped_callback(request, *callback_args, **callback_kwargs)
  File "/backend/backend/views.py", line 56, in index
    if currentUser['images'] and currentUser['images'][0]:
       ~~~~~~~~~~~^^^^^^^^^^
KeyError: 'images'
Not Found: /getToken/
Not Found: /getToken/
HTTP Request: POST https://api.openai.com/v1/chat/completions "HTTP/1.1 200 OK"
HTTP Request: POST https://api.openai.com/v1/chat/completions "HTTP/1.1 200 OK"
Internal Server Error: /
Traceback (most recent call last):
  File "/usr/local/lib/python3.13/site-packages/django/core/handlers/exception.py", line 55, in inner
    response = get_response(request)
  File "/usr/local/lib/python3.13/site-packages/django/core/handlers/base.py", line 197, in _get_response
    response = wrapped_callback(request, *callback_args, **callback_kwargs)
  File "/backend/backend/views.py", line 56, in index
    if currentUser['images'] and currentUser['images'][0]:
       ~~~~~~~~~~~^^^^^^^^^^
KeyError: 'images'
Internal Server Error: /
Traceback (most recent call last):
  File "/usr/local/lib/python3.13/site-packages/django/core/handlers/exception.py", line 55, in inner
    response = get_response(request)
  File "/usr/local/lib/python3.13/site-packages/django/core/handlers/base.py", line 197, in _get_response
    response = wrapped_callback(request, *callback_args, **callback_kwargs)
  File "/backend/backend/views.py", line 56, in index
    if currentUser['images'] and currentUser['images'][0]:
       ~~~~~~~~~~~^^^^^^^^^^
KeyError: 'images'
HTTP Request: POST https://api.openai.com/v1/chat/completions "HTTP/1.1 200 OK"
HTTP Request: POST https://api.openai.com/v1/chat/completions "HTTP/1.1 200 OK"
Authorization code received: AQATL8uSrVFY1tnt62xpu8yvNzzMinku4NQifVXWqXIlwUdJnxkT6n0fvaUzwStWSQny9kHFW4sa1lyJc-wSgwzhAban_zxQGxir07F4lVZiwtBTtyc1FaSQ-4lwOsqdRKronVi7IvmZtEy2UoaLBTmwjD6aXa-IWxCOlUIxcB0qRV-___5U3nOoR1INIRTHYqn_FUpttxvRf6VTKVEqRlskQ5eOLdZX_x8M96eXBERgBSRNhXmm3-fCXEqdChUnfD6bI51OqY08EQOXPKTs1XMPsmrHgLH3P8cHTYgWcH3OXdBg4lqWbH2FHqgw6d3gIupCX0dXA9SrjxcnLI9vUuu38h5_VXaqefcXFBb0b_M90nHdyND4aQmFBEXOeq9uQ6969do_5hyNEz-H0Q
Token info received: {'access_token': 'BQDRrSgPy8owEDLkQv_3rUvnjcF-tyegv3fRSXSDiDucY-QOWMDKbCN38gvc2aRAB8RP8Cf7G_pcKnLpkTaR1xsegp0xcsJfaKKpUsSA4ktCtoNxWHdEcgHvY7JjHY-FD5kCl2jAEfOgZMik0eVWkB4Ze7CQfxxnTkZEYYyn9moPvxeCv6mqj30RoDwsFplcFr5LrRtiS__KCf1ApUg5CSYicgD8aiBY6wECMBZ86_1rg6_9pS9PsLh0egYbKxc6XWOwaQiPDpSWVPGvSVSI-PqLWZSPEP8', 'token_type': 'Bearer', 'expires_in': 3600, 'refresh_token': 'AQA2frsq4boJOy701CcX_vu8QvegE2CWxxOOL2Y9RbEsikBTqzLxu4vfrimSOxHrzlY6mWJiJruKAY4_SqKkLXG-RLM1-YcfpBIDH75rD3Ig5aQA9gxcw17Kh4jZnJpjVyQ', 'scope': 'user-library-read user-read-email user-top-read user-read-private user-follow-read playlist-read-private playlist-read-collaborative app-remote-control streaming ', 'expires_at': 1740540349}
https://i.scdn.co/image/ab67616d00001e024ae1c4c5c45aabe565499163
https://image-cdn-ak.spotifycdn.com/image/ab67706c0000da848bc80c95b9d248cf462c0bd1
HTTP Request: POST https://api.openai.com/v1/chat/completions "HTTP/1.1 200 OK"
HTTP Request: POST https://api.openai.com/v1/chat/completions "HTTP/1.1 200 OK"
HTTP Request: POST https://api.openai.com/v1/chat/completions "HTTP/1.1 200 OK"
HTTP Request: POST https://api.openai.com/v1/chat/completions "HTTP/1.1 200 OK"
HTTP Request: POST https://api.openai.com/v1/chat/completions "HTTP/1.1 200 OK"
HTTP Request: POST https://api.openai.com/v1/chat/completions "HTTP/1.1 200 OK"
HTTP Request: POST https://api.openai.com/v1/chat/completions "HTTP/1.1 200 OK"
HTTP Request: POST https://api.openai.com/v1/chat/completions "HTTP/1.1 200 OK"
HTTP Request: POST https://api.openai.com/v1/chat/completions "HTTP/1.1 200 OK"
HTTP Request: POST https://api.openai.com/v1/chat/completions "HTTP/1.1 200 OK"
HTTP Request: POST https://api.openai.com/v1/chat/completions "HTTP/1.1 200 OK"
HTTP Request: POST https://api.openai.com/v1/chat/completions "HTTP/1.1 200 OK"
HTTP Request: POST https://api.openai.com/v1/chat/completions "HTTP/1.1 200 OK"
HTTP Request: POST https://api.openai.com/v1/chat/completions "HTTP/1.1 200 OK"
Not Found: /getToken/
Not Found: /getToken/
Internal Server Error: /
Traceback (most recent call last):
  File "/usr/local/lib/python3.13/site-packages/django/core/handlers/exception.py", line 55, in inner
    response = get_response(request)
  File "/usr/local/lib/python3.13/site-packages/django/core/handlers/base.py", line 197, in _get_response
    response = wrapped_callback(request, *callback_args, **callback_kwargs)
  File "/backend/backend/views.py", line 56, in index
    if currentUser['images'] and currentUser['images'][0]:
       ~~~~~~~~~~~^^^^^^^^^^
KeyError: 'images'
Internal Server Error: /
Traceback (most recent call last):
  File "/usr/local/lib/python3.13/site-packages/django/core/handlers/exception.py", line 55, in inner
    response = get_response(request)
  File "/usr/local/lib/python3.13/site-packages/django/core/handlers/base.py", line 197, in _get_response
    response = wrapped_callback(request, *callback_args, **callback_kwargs)
  File "/backend/backend/views.py", line 56, in index
    if currentUser['images'] and currentUser['images'][0]:
       ~~~~~~~~~~~^^^^^^^^^^
KeyError: 'images'
HTTP Request: POST https://api.openai.com/v1/chat/completions "HTTP/1.1 200 OK"
HTTP Request: POST https://api.openai.com/v1/chat/completions "HTTP/1.1 200 OK"
Couldn't delete cache at: .cache
Not Found: /getToken/
Not Found: /getToken/
Internal Server Error: /
Traceback (most recent call last):
  File "/usr/local/lib/python3.13/site-packages/django/core/handlers/exception.py", line 55, in inner
    response = get_response(request)
  File "/usr/local/lib/python3.13/site-packages/django/core/handlers/base.py", line 197, in _get_response
    response = wrapped_callback(request, *callback_args, **callback_kwargs)
  File "/backend/backend/views.py", line 56, in index
    if currentUser['images'] and currentUser['images'][0]:
       ~~~~~~~~~~~^^^^^^^^^^
KeyError: 'images'
Internal Server Error: /
Traceback (most recent call last):
  File "/usr/local/lib/python3.13/site-packages/django/core/handlers/exception.py", line 55, in inner
    response = get_response(request)
  File "/usr/local/lib/python3.13/site-packages/django/core/handlers/base.py", line 197, in _get_response
    response = wrapped_callback(request, *callback_args, **callback_kwargs)
  File "/backend/backend/views.py", line 56, in index
    if currentUser['images'] and currentUser['images'][0]:
       ~~~~~~~~~~~^^^^^^^^^^
KeyError: 'images'
HTTP Request: POST https://api.openai.com/v1/chat/completions "HTTP/1.1 200 OK"
HTTP Request: POST https://api.openai.com/v1/chat/completions "HTTP/1.1 200 OK"
Not Found: /getToken/
Not Found: /getToken/
Internal Server Error: /
Traceback (most recent call last):
  File "/usr/local/lib/python3.13/site-packages/django/core/handlers/exception.py", line 55, in inner
    response = get_response(request)
  File "/usr/local/lib/python3.13/site-packages/django/core/handlers/base.py", line 197, in _get_response
    response = wrapped_callback(request, *callback_args, **callback_kwargs)
  File "/backend/backend/views.py", line 56, in index
    if currentUser['images'] and currentUser['images'][0]:
       ~~~~~~~~~~~^^^^^^^^^^
KeyError: 'images'
Internal Server Error: /
Traceback (most recent call last):
  File "/usr/local/lib/python3.13/site-packages/django/core/handlers/exception.py", line 55, in inner
    response = get_response(request)
  File "/usr/local/lib/python3.13/site-packages/django/core/handlers/base.py", line 197, in _get_response
    response = wrapped_callback(request, *callback_args, **callback_kwargs)
  File "/backend/backend/views.py", line 56, in index
    if currentUser['images'] and currentUser['images'][0]:
       ~~~~~~~~~~~^^^^^^^^^^
KeyError: 'images'
HTTP Request: POST https://api.openai.com/v1/chat/completions "HTTP/1.1 200 OK"
HTTP Request: POST https://api.openai.com/v1/chat/completions "HTTP/1.1 200 OK"
Internal Server Error: /
Traceback (most recent call last):
  File "/usr/local/lib/python3.13/site-packages/django/core/handlers/exception.py", line 55, in inner
    response = get_response(request)
  File "/usr/local/lib/python3.13/site-packages/django/core/handlers/base.py", line 197, in _get_response
    response = wrapped_callback(request, *callback_args, **callback_kwargs)
  File "/backend/backend/views.py", line 56, in index
    if currentUser['images'] and currentUser['images'][0]:
       ~~~~~~~~~~~^^^^^^^^^^
KeyError: 'images'
Internal Server Error: /
Traceback (most recent call last):
  File "/usr/local/lib/python3.13/site-packages/django/core/handlers/exception.py", line 55, in inner
    response = get_response(request)
  File "/usr/local/lib/python3.13/site-packages/django/core/handlers/base.py", line 197, in _get_response
    response = wrapped_callback(request, *callback_args, **callback_kwargs)
  File "/backend/backend/views.py", line 56, in index
    if currentUser['images'] and currentUser['images'][0]:
       ~~~~~~~~~~~^^^^^^^^^^
KeyError: 'images'
HTTP Request: POST https://api.openai.com/v1/chat/completions "HTTP/1.1 200 OK"
HTTP Request: POST https://api.openai.com/v1/chat/completions "HTTP/1.1 200 OK"
Not Found: /getToken/
Not Found: /getToken/
Internal Server Error: /
Traceback (most recent call last):
  File "/usr/local/lib/python3.13/site-packages/django/core/handlers/exception.py", line 55, in inner
    response = get_response(request)
  File "/usr/local/lib/python3.13/site-packages/django/core/handlers/base.py", line 197, in _get_response
    response = wrapped_callback(request, *callback_args, **callback_kwargs)
  File "/backend/backend/views.py", line 56, in index
    if currentUser['images'] and currentUser['images'][0]:
       ~~~~~~~~~~~^^^^^^^^^^
KeyError: 'images'
Internal Server Error: /
Traceback (most recent call last):
  File "/usr/local/lib/python3.13/site-packages/django/core/handlers/exception.py", line 55, in inner
    response = get_response(request)
  File "/usr/local/lib/python3.13/site-packages/django/core/handlers/base.py", line 197, in _get_response
    response = wrapped_callback(request, *callback_args, **callback_kwargs)
  File "/backend/backend/views.py", line 56, in index
    if currentUser['images'] and currentUser['images'][0]:
       ~~~~~~~~~~~^^^^^^^^^^
KeyError: 'images'
HTTP Request: POST https://api.openai.com/v1/chat/completions "HTTP/1.1 200 OK"
HTTP Request: POST https://api.openai.com/v1/chat/completions "HTTP/1.1 200 OK"
Internal Server Error: /
Traceback (most recent call last):
  File "/usr/local/lib/python3.13/site-packages/django/core/handlers/exception.py", line 55, in inner
    response = get_response(request)
  File "/usr/local/lib/python3.13/site-packages/django/core/handlers/base.py", line 197, in _get_response
    response = wrapped_callback(request, *callback_args, **callback_kwargs)
  File "/backend/backend/views.py", line 56, in index
    if currentUser['images'] and currentUser['images'][0]:
       ~~~~~~~~~~~^^^^^^^^^^
KeyError: 'images'
Internal Server Error: /
Traceback (most recent call last):
  File "/usr/local/lib/python3.13/site-packages/django/core/handlers/exception.py", line 55, in inner
    response = get_response(request)
  File "/usr/local/lib/python3.13/site-packages/django/core/handlers/base.py", line 197, in _get_response
    response = wrapped_callback(request, *callback_args, **callback_kwargs)
  File "/backend/backend/views.py", line 56, in index
    if currentUser['images'] and currentUser['images'][0]:
       ~~~~~~~~~~~^^^^^^^^^^
KeyError: 'images'
HTTP Request: POST https://api.openai.com/v1/chat/completions "HTTP/1.1 200 OK"
HTTP Request: POST https://api.openai.com/v1/chat/completions "HTTP/1.1 200 OK"
Authorization code received: AQCfLRmoGyNUBRjRzxSyw2yJhuG4wVFKWxb_VENfkbBHuar0dMTYYRdBIMv67rwqdaL6XGOioe6SDt-RYni-WjSc4Fix64AqverYV00QjDnPFhUzB-dyKDtEadaYj1ZipWv4qPltqDsvXLxid3TSSMg3tlmgt-Xf0yrsVYfXh3YlnKkVE8LSrj-EMljiEu6t2fogE-fHO_dbsoj3dtpn5Xpy_NCdgJtJSB0FESsLFw609sRLWCRKdFoG8aMXvE92ay6lc3Mf8-QDx63YHm8x1s-inNAGHHkrUOVxdVVpQfplcF5DNuF2MtfqbpAFQZ9Y31UvJFMfXT0ZhKKh-PPfK6UrQzwF-PJGaRZgeK9hM2xDQSeEdujLde6JK317HfTTD6c1H0Cfwbw85EXBRA
Token info received: {'access_token': 'BQBXM6ZH1VedPMB6FImSa34RV8cJjZUHdwJNqhKznug7WaVP_8mQUeI3NzavBSNpdx7LHo4OMyTN_uQM7wMON3tfjjyuH0PvjsxDHlX7rZccLJ3qkvt31W7DwWqWssAx4M9HAhFlAr_NWCdoEPTCYUFj47sm0D7jBY-E3cdl6V3yn8tAGAUxcK0nd4Dtdebt9szAIpx0Y9RI6RpONfLiXCEMSS1331w_5s9lk_xvTOrrmSMt34mHZ7DNJwzBtDI2G_xmZ_DwhYdkGkMm0w29GJ6NjNvp4bk', 'token_type': 'Bearer', 'expires_in': 3600, 'refresh_token': 'AQCMogl2YAvok0CafaiEFfVsLSG8oLMXQpTOhRPfQlEEiliMIvYWJ8vFUgBSVwiNHh2USFERIChoysLeFs1v35Ii1SXaXjF27NzECGvPEazOy3bgWEhrsNmXKsb0IaTyV8k', 'scope': 'user-library-read user-read-email user-top-read user-read-private user-follow-read playlist-read-private playlist-read-collaborative app-remote-control streaming ', 'expires_at': 1740545971}
https://i.scdn.co/image/ab67616d00001e024ae1c4c5c45aabe565499163
https://image-cdn-ak.spotifycdn.com/image/ab67706c0000da848bc80c95b9d248cf462c0bd1
HTTP Request: POST https://api.openai.com/v1/chat/completions "HTTP/1.1 200 OK"
HTTP Request: POST https://api.openai.com/v1/chat/completions "HTTP/1.1 200 OK"
Watching for file changes with StatReloader
Watching for file changes with StatReloader
Watching for file changes with StatReloader
HTTP Request: POST https://api.openai.com/v1/chat/completions "HTTP/1.1 200 OK"
HTTP Request: POST https://api.openai.com/v1/chat/completions "HTTP/1.1 200 OK"
HTTP Request: POST https://api.openai.com/v1/chat/completions "HTTP/1.1 200 OK"
HTTP Request: POST https://api.openai.com/v1/chat/completions "HTTP/1.1 200 OK"
